2022-05-09 23:40:27,065: User's personal data received (2008767674):
{'deleted': False, 'firstname': 'Вовг', 'lastname': 'Гк', 'subdivision': 'Швшв', 'email': '. @', 'phonenumber': '66'}
2022-05-09 23:40:27,147: Infinity polling exception: name 'PhrasesGenerator' is not defined
2022-05-09 23:40:27,173: Exception traceback:
Traceback (most recent call last):
  File "C:\Users\apukh\AppData\Local\Programs\Python\Python310\lib\site-packages\telebot\__init__.py", line 617, in infinity_polling
    self.polling(none_stop=True, timeout=timeout, long_polling_timeout=long_polling_timeout,
  File "C:\Users\apukh\AppData\Local\Programs\Python\Python310\lib\site-packages\telebot\__init__.py", line 664, in polling
    self.__threaded_polling(non_stop, interval, timeout, long_polling_timeout, allowed_updates)
  File "C:\Users\apukh\AppData\Local\Programs\Python\Python310\lib\site-packages\telebot\__init__.py", line 726, in __threaded_polling
    raise e
  File "C:\Users\apukh\AppData\Local\Programs\Python\Python310\lib\site-packages\telebot\__init__.py", line 686, in __threaded_polling
    self.worker_pool.raise_exceptions()
  File "C:\Users\apukh\AppData\Local\Programs\Python\Python310\lib\site-packages\telebot\util.py", line 135, in raise_exceptions
    raise self.exception_info
  File "C:\Users\apukh\AppData\Local\Programs\Python\Python310\lib\site-packages\telebot\util.py", line 87, in run
    task(*args, **kwargs)
  File "C:\Users\apukh\OneDrive\Документы\TelegramBotAssistant\WithDataWorker.py", line 152, in get_phone_number
    self.finish_process_new_user(message, new_user_dict, add_user_to_problems_f, user_get_f)
  File "C:\Users\apukh\OneDrive\Документы\TelegramBotAssistant\WithDataWorker.py", line 162, in finish_process_new_user
    user_get_f(message)
  File "C:\Users\apukh\OneDrive\Документы\TelegramBotAssistant\WithProblemsWorker.py", line 112, in get_new_problem
    self.bot.send_photo(str(message.chat.id), PhrasesGenerator.get_text_with_input_suggestion()[1],
NameError: name 'PhrasesGenerator' is not defined

2022-05-09 23:40:56,693: Infinity polling exception: name 'PhotosFromMessageGetter' is not defined
2022-05-09 23:40:56,697: Exception traceback:
Traceback (most recent call last):
  File "C:\Users\apukh\AppData\Local\Programs\Python\Python310\lib\site-packages\telebot\__init__.py", line 617, in infinity_polling
    self.polling(none_stop=True, timeout=timeout, long_polling_timeout=long_polling_timeout,
  File "C:\Users\apukh\AppData\Local\Programs\Python\Python310\lib\site-packages\telebot\__init__.py", line 664, in polling
    self.__threaded_polling(non_stop, interval, timeout, long_polling_timeout, allowed_updates)
  File "C:\Users\apukh\AppData\Local\Programs\Python\Python310\lib\site-packages\telebot\__init__.py", line 726, in __threaded_polling
    raise e
  File "C:\Users\apukh\AppData\Local\Programs\Python\Python310\lib\site-packages\telebot\__init__.py", line 686, in __threaded_polling
    self.worker_pool.raise_exceptions()
  File "C:\Users\apukh\AppData\Local\Programs\Python\Python310\lib\site-packages\telebot\util.py", line 135, in raise_exceptions
    raise self.exception_info
  File "C:\Users\apukh\AppData\Local\Programs\Python\Python310\lib\site-packages\telebot\util.py", line 87, in run
    task(*args, **kwargs)
  File "C:\Users\apukh\OneDrive\Документы\TelegramBotAssistant\WithProblemsWorker.py", line 139, in process_new_problem
    self.start_get_photos(message, new_problem_dict)
  File "C:\Users\apukh\OneDrive\Документы\TelegramBotAssistant\WithProblemsWorker.py", line 150, in start_get_photos
    photo_dict = PhotosFromMessageGetter.get_photo_from_message(self.bot, message)
NameError: name 'PhotosFromMessageGetter' is not defined

2022-05-09 23:42:08,503: Infinity polling exception: module 'datetime' has no attribute 'today'
2022-05-09 23:42:08,509: Exception traceback:
Traceback (most recent call last):
  File "C:\Users\apukh\AppData\Local\Programs\Python\Python310\lib\site-packages\telebot\__init__.py", line 617, in infinity_polling
    self.polling(none_stop=True, timeout=timeout, long_polling_timeout=long_polling_timeout,
  File "C:\Users\apukh\AppData\Local\Programs\Python\Python310\lib\site-packages\telebot\__init__.py", line 664, in polling
    self.__threaded_polling(non_stop, interval, timeout, long_polling_timeout, allowed_updates)
  File "C:\Users\apukh\AppData\Local\Programs\Python\Python310\lib\site-packages\telebot\__init__.py", line 726, in __threaded_polling
    raise e
  File "C:\Users\apukh\AppData\Local\Programs\Python\Python310\lib\site-packages\telebot\__init__.py", line 686, in __threaded_polling
    self.worker_pool.raise_exceptions()
  File "C:\Users\apukh\AppData\Local\Programs\Python\Python310\lib\site-packages\telebot\util.py", line 135, in raise_exceptions
    raise self.exception_info
  File "C:\Users\apukh\AppData\Local\Programs\Python\Python310\lib\site-packages\telebot\util.py", line 87, in run
    task(*args, **kwargs)
  File "C:\Users\apukh\OneDrive\Документы\TelegramBotAssistant\WithProblemsWorker.py", line 140, in process_new_problem
    self.start_get_photos(message, new_problem_dict)
  File "C:\Users\apukh\OneDrive\Документы\TelegramBotAssistant\WithProblemsWorker.py", line 158, in start_get_photos
    self.finish_process_new_problem(message, new_problem_dict)
  File "C:\Users\apukh\OneDrive\Документы\TelegramBotAssistant\WithProblemsWorker.py", line 161, in finish_process_new_problem
    self.add_new_problem(str(message.chat.id), new_problem_dict)
  File "C:\Users\apukh\OneDrive\Документы\TelegramBotAssistant\WithProblemsWorker.py", line 71, in add_new_problem
    date_key = datetime.today().strftime("%d.%m.%y %H:%M:%S")
AttributeError: module 'datetime' has no attribute 'today'

2022-05-09 23:42:46,207: Problem added as number 2 by user 2008767674
 {'issolved': False, 'next_reminder': 1652129685, 'date': 1652128965, 'text': 'Лкл', 'number': 2, 'photos': [{'name': 'AgACAgIAAxkBAAEBZjxieXzOu4OBkcnIwtmK1_ubJY8LxAACN7oxG0Wb0Eu-oxjaXhoPkAEAAwIAA3kAAyQE.jpg', 'media_group_id': '13217031798546194'}], 'howPointsToSendToOperator': 3}
2022-05-09 23:42:46,261: Photo by For 2008767674
2022-05-09 23:42:51,030: Exception in sending to the operator via telegram:
A request to the Telegram API was unsuccessful. Error code: 400. Description: Bad Request: chat not found
Traceback (most recent call last):
  File "C:\Users\apukh\OneDrive\Документы\TelegramBotAssistant\ToOperatorByTelegramSender.py", line 34, in send_to_operator
    bot.send_media_group(operator_data["chat_id"], media)
  File "C:\Users\apukh\AppData\Local\Programs\Python\Python310\lib\site-packages\telebot\__init__.py", line 1355, in send_media_group
    result = apihelper.send_media_group(
  File "C:\Users\apukh\AppData\Local\Programs\Python\Python310\lib\site-packages\telebot\apihelper.py", line 496, in send_media_group
    return _make_request(
  File "C:\Users\apukh\AppData\Local\Programs\Python\Python310\lib\site-packages\telebot\apihelper.py", line 157, in _make_request
    json_result = _check_result(method_name, result)
  File "C:\Users\apukh\AppData\Local\Programs\Python\Python310\lib\site-packages\telebot\apihelper.py", line 184, in _check_result
    raise ApiTelegramException(method_name, result, result_json)
telebot.apihelper.ApiTelegramException: A request to the Telegram API was unsuccessful. Error code: 400. Description: Bad Request: chat not found
2022-05-09 23:42:57,560: Problem added as number 3 by user 2008767674
 {'issolved': False, 'next_reminder': 1652129697, 'date': 1652128977, 'text': 'Гг', 'number': 3, 'photos': [], 'howPointsToSendToOperator': 3}
2022-05-09 23:43:01,840: Exception in sending to the operator via telegram:
A request to the Telegram API was unsuccessful. Error code: 400. Description: Bad Request: chat not found
Traceback (most recent call last):
  File "C:\Users\apukh\OneDrive\Документы\TelegramBotAssistant\ToOperatorByTelegramSender.py", line 23, in send_to_operator
    bot.send_message(operator_data["chat_id"], text)
  File "C:\Users\apukh\AppData\Local\Programs\Python\Python310\lib\site-packages\telebot\__init__.py", line 969, in send_message
    apihelper.send_message(
  File "C:\Users\apukh\AppData\Local\Programs\Python\Python310\lib\site-packages\telebot\apihelper.py", line 269, in send_message
    return _make_request(token, method_url, params=payload, method='post')
  File "C:\Users\apukh\AppData\Local\Programs\Python\Python310\lib\site-packages\telebot\apihelper.py", line 157, in _make_request
    json_result = _check_result(method_name, result)
  File "C:\Users\apukh\AppData\Local\Programs\Python\Python310\lib\site-packages\telebot\apihelper.py", line 184, in _check_result
    raise ApiTelegramException(method_name, result, result_json)
telebot.apihelper.ApiTelegramException: A request to the Telegram API was unsuccessful. Error code: 400. Description: Bad Request: chat not found
2022-05-09 23:43:45,541: User's personal data received (1235662078):
{'deleted': False, 'firstname': 'asdf', 'lastname': 'asdf', 'subdivision': 'fdeg', 'email': '.@', 'phonenumber': '234'}
2022-05-09 23:43:48,858: Problem added as number 4 by user 1235662078
 {'issolved': False, 'next_reminder': 1652129748, 'date': 1652129028, 'text': ';lkj', 'number': 4, 'photos': [], 'howPointsToSendToOperator': 3}
2022-05-09 23:43:53,144: Exception in sending to the operator via telegram:
A request to the Telegram API was unsuccessful. Error code: 400. Description: Bad Request: chat not found
Traceback (most recent call last):
  File "C:\Users\apukh\OneDrive\Документы\TelegramBotAssistant\ToOperatorByTelegramSender.py", line 23, in send_to_operator
    bot.send_message(operator_data["chat_id"], text)
  File "C:\Users\apukh\AppData\Local\Programs\Python\Python310\lib\site-packages\telebot\__init__.py", line 969, in send_message
    apihelper.send_message(
  File "C:\Users\apukh\AppData\Local\Programs\Python\Python310\lib\site-packages\telebot\apihelper.py", line 269, in send_message
    return _make_request(token, method_url, params=payload, method='post')
  File "C:\Users\apukh\AppData\Local\Programs\Python\Python310\lib\site-packages\telebot\apihelper.py", line 157, in _make_request
    json_result = _check_result(method_name, result)
  File "C:\Users\apukh\AppData\Local\Programs\Python\Python310\lib\site-packages\telebot\apihelper.py", line 184, in _check_result
    raise ApiTelegramException(method_name, result, result_json)
telebot.apihelper.ApiTelegramException: A request to the Telegram API was unsuccessful. Error code: 400. Description: Bad Request: chat not found
2022-05-09 23:44:34,929: Problem added as number 5 by user 2008767674
 {'issolved': False, 'next_reminder': 1652129794, 'date': 1652129074, 'text': 'Паеооеоеое', 'number': 5, 'photos': [], 'howPointsToSendToOperator': 3}
2022-05-09 23:45:59,047: User's personal data received (2008767674):
{'deleted': False, 'firstname': 'Кшкш', 'lastname': '6к6к', 'subdivision': 'Шк7', 'email': '. @', 'phonenumber': '737'}
2022-05-09 23:52:30,249: Problem added as number 6 by user 2008767674
 {'issolved': False, 'next_reminder': 1652130270, 'date': 1652129550, 'text': 'Гвг', 'number': 6, 'photos': [], 'howPointsToSendToOperator': 3}
2022-05-09 23:52:34,370: Exception in sending to the operator via telegram:
A request to the Telegram API was unsuccessful. Error code: 400. Description: Bad Request: chat not found
Traceback (most recent call last):
  File "C:\Users\apukh\OneDrive\Документы\TelegramBotAssistant\ToOperatorByTelegramSender.py", line 23, in send_to_operator
    bot.send_message(operator_data["chat_id"], text)
  File "C:\Users\apukh\AppData\Local\Programs\Python\Python310\lib\site-packages\telebot\__init__.py", line 969, in send_message
    apihelper.send_message(
  File "C:\Users\apukh\AppData\Local\Programs\Python\Python310\lib\site-packages\telebot\apihelper.py", line 269, in send_message
    return _make_request(token, method_url, params=payload, method='post')
  File "C:\Users\apukh\AppData\Local\Programs\Python\Python310\lib\site-packages\telebot\apihelper.py", line 157, in _make_request
    json_result = _check_result(method_name, result)
  File "C:\Users\apukh\AppData\Local\Programs\Python\Python310\lib\site-packages\telebot\apihelper.py", line 184, in _check_result
    raise ApiTelegramException(method_name, result, result_json)
telebot.apihelper.ApiTelegramException: A request to the Telegram API was unsuccessful. Error code: 400. Description: Bad Request: chat not found
2022-05-09 23:53:47,637: User's personal data received (2008767674):
{'deleted': False, 'firstname': 'Гкг', 'lastname': 'Гг', 'subdivision': 'Рг', 'email': '. @', 'phonenumber': 'Окл'}
2022-05-09 23:53:49,855: Problem added as number 0 by user 2008767674
 {'issolved': False, 'next_reminder': 1652130349, 'date': 1652129629, 'text': '737', 'number': 0, 'photos': [], 'howPointsToSendToOperator': 3}
2022-05-09 23:53:53,571: Exception in sending to the operator via telegram:
A request to the Telegram API was unsuccessful. Error code: 400. Description: Bad Request: chat not found
Traceback (most recent call last):
  File "C:\Users\apukh\OneDrive\Документы\TelegramBotAssistant\ToOperatorByTelegramSender.py", line 23, in send_to_operator
    bot.send_message(operator_data["chat_id"], text)
  File "C:\Users\apukh\AppData\Local\Programs\Python\Python310\lib\site-packages\telebot\__init__.py", line 969, in send_message
    apihelper.send_message(
  File "C:\Users\apukh\AppData\Local\Programs\Python\Python310\lib\site-packages\telebot\apihelper.py", line 269, in send_message
    return _make_request(token, method_url, params=payload, method='post')
  File "C:\Users\apukh\AppData\Local\Programs\Python\Python310\lib\site-packages\telebot\apihelper.py", line 157, in _make_request
    json_result = _check_result(method_name, result)
  File "C:\Users\apukh\AppData\Local\Programs\Python\Python310\lib\site-packages\telebot\apihelper.py", line 184, in _check_result
    raise ApiTelegramException(method_name, result, result_json)
telebot.apihelper.ApiTelegramException: A request to the Telegram API was unsuccessful. Error code: 400. Description: Bad Request: chat not found
2022-05-09 23:56:25,463: Problem added as number 1 by user 2008767674
 {'issolved': False, 'next_reminder': 1652130505, 'date': 1652129785, 'text': '66к', 'number': 1, 'photos': [], 'howPointsToSendToOperator': 3}
2022-05-09 23:56:25,746: Exception in sending to the operator via telegram:
A request to the Telegram API was unsuccessful. Error code: 400. Description: Bad Request: chat not found
Traceback (most recent call last):
  File "C:\Users\apukh\OneDrive\Документы\TelegramBotAssistant\ToOperatorByTelegramSender.py", line 23, in send_to_operator
    bot.send_message(operator_data["chat_id"], text)
  File "C:\Users\apukh\AppData\Local\Programs\Python\Python310\lib\site-packages\telebot\__init__.py", line 969, in send_message
    apihelper.send_message(
  File "C:\Users\apukh\AppData\Local\Programs\Python\Python310\lib\site-packages\telebot\apihelper.py", line 269, in send_message
    return _make_request(token, method_url, params=payload, method='post')
  File "C:\Users\apukh\AppData\Local\Programs\Python\Python310\lib\site-packages\telebot\apihelper.py", line 157, in _make_request
    json_result = _check_result(method_name, result)
  File "C:\Users\apukh\AppData\Local\Programs\Python\Python310\lib\site-packages\telebot\apihelper.py", line 184, in _check_result
    raise ApiTelegramException(method_name, result, result_json)
telebot.apihelper.ApiTelegramException: A request to the Telegram API was unsuccessful. Error code: 400. Description: Bad Request: chat not found
2022-05-10 00:06:30,112: User's personal data received (2008767674):
{'deleted': False, 'firstname': 'Гкг', 'lastname': 'Угуг', 'subdivision': '. @', 'email': '. @', 'phonenumber': '3773'}
2022-05-10 00:06:31,702: Problem added as number 0 by user 2008767674
 {'issolved': False, 'next_reminder': 1652131111, 'date': 1652130391, 'text': 'Гвг', 'number': 0, 'photos': [], 'howPointsToSendToOperator': 3}
2022-05-10 00:06:37,034: Exception in sending to the operator via telegram:
A request to the Telegram API was unsuccessful. Error code: 400. Description: Bad Request: chat not found
Traceback (most recent call last):
  File "C:\Users\apukh\OneDrive\Документы\TelegramBotAssistant\ToOperatorByTelegramSender.py", line 23, in send_to_operator
    bot.send_message(operator_data["chat_id"], text)
  File "C:\Users\apukh\AppData\Local\Programs\Python\Python310\lib\site-packages\telebot\__init__.py", line 969, in send_message
    apihelper.send_message(
  File "C:\Users\apukh\AppData\Local\Programs\Python\Python310\lib\site-packages\telebot\apihelper.py", line 269, in send_message
    return _make_request(token, method_url, params=payload, method='post')
  File "C:\Users\apukh\AppData\Local\Programs\Python\Python310\lib\site-packages\telebot\apihelper.py", line 157, in _make_request
    json_result = _check_result(method_name, result)
  File "C:\Users\apukh\AppData\Local\Programs\Python\Python310\lib\site-packages\telebot\apihelper.py", line 184, in _check_result
    raise ApiTelegramException(method_name, result, result_json)
telebot.apihelper.ApiTelegramException: A request to the Telegram API was unsuccessful. Error code: 400. Description: Bad Request: chat not found
2022-05-10 00:06:48,791: User's personal data received (1235662078):
{'deleted': False, 'firstname': 'asd;kjl', 'lastname': 'asd;kf', 'subdivision': 'as', 'email': '.@', 'phonenumber': '435'}
2022-05-10 00:08:04,308: Exception in sending to the operator via telegram:
A request to the Telegram API was unsuccessful. Error code: 400. Description: Bad Request: chat not found
Traceback (most recent call last):
  File "C:\Users\apukh\OneDrive\Документы\TelegramBotAssistant\ToOperatorByTelegramSender.py", line 23, in send_to_operator
    bot.send_message(operator_data["chat_id"], text)
  File "C:\Users\apukh\AppData\Local\Programs\Python\Python310\lib\site-packages\telebot\__init__.py", line 969, in send_message
    apihelper.send_message(
  File "C:\Users\apukh\AppData\Local\Programs\Python\Python310\lib\site-packages\telebot\apihelper.py", line 269, in send_message
    return _make_request(token, method_url, params=payload, method='post')
  File "C:\Users\apukh\AppData\Local\Programs\Python\Python310\lib\site-packages\telebot\apihelper.py", line 157, in _make_request
    json_result = _check_result(method_name, result)
  File "C:\Users\apukh\AppData\Local\Programs\Python\Python310\lib\site-packages\telebot\apihelper.py", line 184, in _check_result
    raise ApiTelegramException(method_name, result, result_json)
telebot.apihelper.ApiTelegramException: A request to the Telegram API was unsuccessful. Error code: 400. Description: Bad Request: chat not found
2022-05-10 00:08:19,819: Problem added as number 1 by user 2008767674
 {'issolved': False, 'next_reminder': 1652131219, 'date': 1652130499, 'text': 'Г4г', 'number': 1, 'photos': [], 'howPointsToSendToOperator': 3}
2022-05-10 00:08:23,918: Exception in sending to the operator via telegram:
A request to the Telegram API was unsuccessful. Error code: 400. Description: Bad Request: chat not found
Traceback (most recent call last):
  File "C:\Users\apukh\OneDrive\Документы\TelegramBotAssistant\ToOperatorByTelegramSender.py", line 23, in send_to_operator
    bot.send_message(operator_data["chat_id"], text)
  File "C:\Users\apukh\AppData\Local\Programs\Python\Python310\lib\site-packages\telebot\__init__.py", line 969, in send_message
    apihelper.send_message(
  File "C:\Users\apukh\AppData\Local\Programs\Python\Python310\lib\site-packages\telebot\apihelper.py", line 269, in send_message
    return _make_request(token, method_url, params=payload, method='post')
  File "C:\Users\apukh\AppData\Local\Programs\Python\Python310\lib\site-packages\telebot\apihelper.py", line 157, in _make_request
    json_result = _check_result(method_name, result)
  File "C:\Users\apukh\AppData\Local\Programs\Python\Python310\lib\site-packages\telebot\apihelper.py", line 184, in _check_result
    raise ApiTelegramException(method_name, result, result_json)
telebot.apihelper.ApiTelegramException: A request to the Telegram API was unsuccessful. Error code: 400. Description: Bad Request: chat not found
2022-05-10 00:08:28,680: Problem added as number 2 by user 1235662078
 {'issolved': False, 'next_reminder': 1652131228, 'date': 1652130508, 'text': 'asdf', 'number': 2, 'photos': [], 'howPointsToSendToOperator': 3}
2022-05-10 00:08:32,159: Exception in sending to the operator via telegram:
A request to the Telegram API was unsuccessful. Error code: 400. Description: Bad Request: chat not found
Traceback (most recent call last):
  File "C:\Users\apukh\OneDrive\Документы\TelegramBotAssistant\ToOperatorByTelegramSender.py", line 23, in send_to_operator
    bot.send_message(operator_data["chat_id"], text)
  File "C:\Users\apukh\AppData\Local\Programs\Python\Python310\lib\site-packages\telebot\__init__.py", line 969, in send_message
    apihelper.send_message(
  File "C:\Users\apukh\AppData\Local\Programs\Python\Python310\lib\site-packages\telebot\apihelper.py", line 269, in send_message
    return _make_request(token, method_url, params=payload, method='post')
  File "C:\Users\apukh\AppData\Local\Programs\Python\Python310\lib\site-packages\telebot\apihelper.py", line 157, in _make_request
    json_result = _check_result(method_name, result)
  File "C:\Users\apukh\AppData\Local\Programs\Python\Python310\lib\site-packages\telebot\apihelper.py", line 184, in _check_result
    raise ApiTelegramException(method_name, result, result_json)
telebot.apihelper.ApiTelegramException: A request to the Telegram API was unsuccessful. Error code: 400. Description: Bad Request: chat not found
2022-05-10 00:08:36,406: Exception in sending to the operator via telegram:
A request to the Telegram API was unsuccessful. Error code: 400. Description: Bad Request: chat not found
Traceback (most recent call last):
  File "C:\Users\apukh\OneDrive\Документы\TelegramBotAssistant\ToOperatorByTelegramSender.py", line 23, in send_to_operator
    bot.send_message(operator_data["chat_id"], text)
  File "C:\Users\apukh\AppData\Local\Programs\Python\Python310\lib\site-packages\telebot\__init__.py", line 969, in send_message
    apihelper.send_message(
  File "C:\Users\apukh\AppData\Local\Programs\Python\Python310\lib\site-packages\telebot\apihelper.py", line 269, in send_message
    return _make_request(token, method_url, params=payload, method='post')
  File "C:\Users\apukh\AppData\Local\Programs\Python\Python310\lib\site-packages\telebot\apihelper.py", line 157, in _make_request
    json_result = _check_result(method_name, result)
  File "C:\Users\apukh\AppData\Local\Programs\Python\Python310\lib\site-packages\telebot\apihelper.py", line 184, in _check_result
    raise ApiTelegramException(method_name, result, result_json)
telebot.apihelper.ApiTelegramException: A request to the Telegram API was unsuccessful. Error code: 400. Description: Bad Request: chat not found
2022-05-14 23:04:43,779: User's personal data received (2008767674):
{'deleted': False, 'firstname': 'Гкгк', 'lastname': 'Гкгк', 'subdivision': 'Нн', 'email': '. @', 'phonenumber': '667'}
2022-05-14 23:04:46,572: Problem added as number 0 by user 2008767674
 {'issolved': False, 'next_reminder': 1652559406, 'date': 1652558686, 'text': 'Лл', 'number': 0, 'photos': [], 'howPointsToSendToOperator': 3}
2022-05-14 23:04:50,029: Exception in sending to the operator via telegram:
A request to the Telegram API was unsuccessful. Error code: 400. Description: Bad Request: chat not found
Traceback (most recent call last):
  File "C:\Users\apukh\OneDrive\Документы\TelegramBotAssistant\ToOperatorByTelegramSender.py", line 23, in send_to_operator
    bot.send_message(operator_data["chat_id"], text)
  File "C:\Users\apukh\AppData\Local\Programs\Python\Python310\lib\site-packages\telebot\__init__.py", line 969, in send_message
    apihelper.send_message(
  File "C:\Users\apukh\AppData\Local\Programs\Python\Python310\lib\site-packages\telebot\apihelper.py", line 269, in send_message
    return _make_request(token, method_url, params=payload, method='post')
  File "C:\Users\apukh\AppData\Local\Programs\Python\Python310\lib\site-packages\telebot\apihelper.py", line 157, in _make_request
    json_result = _check_result(method_name, result)
  File "C:\Users\apukh\AppData\Local\Programs\Python\Python310\lib\site-packages\telebot\apihelper.py", line 184, in _check_result
    raise ApiTelegramException(method_name, result, result_json)
telebot.apihelper.ApiTelegramException: A request to the Telegram API was unsuccessful. Error code: 400. Description: Bad Request: chat not found
2022-05-14 23:05:06,366: Problem added as number 1 by user 2008767674
 {'issolved': False, 'next_reminder': 1652559426, 'date': 1652558706, 'text': 'К66к', 'number': 1, 'photos': [], 'howPointsToSendToOperator': 3}
2022-05-14 23:05:09,998: Exception in sending to the operator via telegram:
A request to the Telegram API was unsuccessful. Error code: 400. Description: Bad Request: chat not found
Traceback (most recent call last):
  File "C:\Users\apukh\OneDrive\Документы\TelegramBotAssistant\ToOperatorByTelegramSender.py", line 23, in send_to_operator
    bot.send_message(operator_data["chat_id"], text)
  File "C:\Users\apukh\AppData\Local\Programs\Python\Python310\lib\site-packages\telebot\__init__.py", line 969, in send_message
    apihelper.send_message(
  File "C:\Users\apukh\AppData\Local\Programs\Python\Python310\lib\site-packages\telebot\apihelper.py", line 269, in send_message
    return _make_request(token, method_url, params=payload, method='post')
  File "C:\Users\apukh\AppData\Local\Programs\Python\Python310\lib\site-packages\telebot\apihelper.py", line 157, in _make_request
    json_result = _check_result(method_name, result)
  File "C:\Users\apukh\AppData\Local\Programs\Python\Python310\lib\site-packages\telebot\apihelper.py", line 184, in _check_result
    raise ApiTelegramException(method_name, result, result_json)
telebot.apihelper.ApiTelegramException: A request to the Telegram API was unsuccessful. Error code: 400. Description: Bad Request: chat not found
2022-05-14 23:05:14,402: Exception in sending to the operator via telegram:
A request to the Telegram API was unsuccessful. Error code: 400. Description: Bad Request: chat not found
Traceback (most recent call last):
  File "C:\Users\apukh\OneDrive\Документы\TelegramBotAssistant\ToOperatorByTelegramSender.py", line 23, in send_to_operator
    bot.send_message(operator_data["chat_id"], text)
  File "C:\Users\apukh\AppData\Local\Programs\Python\Python310\lib\site-packages\telebot\__init__.py", line 969, in send_message
    apihelper.send_message(
  File "C:\Users\apukh\AppData\Local\Programs\Python\Python310\lib\site-packages\telebot\apihelper.py", line 269, in send_message
    return _make_request(token, method_url, params=payload, method='post')
  File "C:\Users\apukh\AppData\Local\Programs\Python\Python310\lib\site-packages\telebot\apihelper.py", line 157, in _make_request
    json_result = _check_result(method_name, result)
  File "C:\Users\apukh\AppData\Local\Programs\Python\Python310\lib\site-packages\telebot\apihelper.py", line 184, in _check_result
    raise ApiTelegramException(method_name, result, result_json)
telebot.apihelper.ApiTelegramException: A request to the Telegram API was unsuccessful. Error code: 400. Description: Bad Request: chat not found
2022-05-14 23:05:21,141: Problem added as number 2 by user 2008767674
 {'issolved': False, 'next_reminder': 1652559441, 'date': 1652558721, 'text': 'Шш', 'number': 2, 'photos': [], 'howPointsToSendToOperator': 3}
2022-05-14 23:05:24,625: Exception in sending to the operator via telegram:
A request to the Telegram API was unsuccessful. Error code: 400. Description: Bad Request: chat not found
Traceback (most recent call last):
  File "C:\Users\apukh\OneDrive\Документы\TelegramBotAssistant\ToOperatorByTelegramSender.py", line 23, in send_to_operator
    bot.send_message(operator_data["chat_id"], text)
  File "C:\Users\apukh\AppData\Local\Programs\Python\Python310\lib\site-packages\telebot\__init__.py", line 969, in send_message
    apihelper.send_message(
  File "C:\Users\apukh\AppData\Local\Programs\Python\Python310\lib\site-packages\telebot\apihelper.py", line 269, in send_message
    return _make_request(token, method_url, params=payload, method='post')
  File "C:\Users\apukh\AppData\Local\Programs\Python\Python310\lib\site-packages\telebot\apihelper.py", line 157, in _make_request
    json_result = _check_result(method_name, result)
  File "C:\Users\apukh\AppData\Local\Programs\Python\Python310\lib\site-packages\telebot\apihelper.py", line 184, in _check_result
    raise ApiTelegramException(method_name, result, result_json)
telebot.apihelper.ApiTelegramException: A request to the Telegram API was unsuccessful. Error code: 400. Description: Bad Request: chat not found
2022-05-20 00:59:30,543: User's personal data received (2008767674):
{'deleted': False, 'firstname': 'hel', 'lastname': 'asdf', 'subdivision': '345', 'email': '.@', 'phonenumber': 'saf'}
2022-05-20 01:01:20,708: Problem added as number 0 by user 2008767674
 {'issolved': False, 'next_reminder': 1652998400, 'date': 1652997680, 'text': 'gfhj', 'number': 0, 'photos': [], 'howPointsToSendToOperator': 3}
2022-05-20 01:01:24,089: Exception in sending to the operator via telegram:
A request to the Telegram API was unsuccessful. Error code: 400. Description: Bad Request: chat not found
Traceback (most recent call last):
  File "C:\Users\apukh\OneDrive\Документы\TelegramBotAssistant\ToOperatorByTelegramSender.py", line 23, in send_to_operator
    bot.send_message(operator_data["chat_id"], text)
  File "C:\Users\apukh\AppData\Local\Programs\Python\Python310\lib\site-packages\telebot\__init__.py", line 969, in send_message
    apihelper.send_message(
  File "C:\Users\apukh\AppData\Local\Programs\Python\Python310\lib\site-packages\telebot\apihelper.py", line 269, in send_message
    return _make_request(token, method_url, params=payload, method='post')
  File "C:\Users\apukh\AppData\Local\Programs\Python\Python310\lib\site-packages\telebot\apihelper.py", line 157, in _make_request
    json_result = _check_result(method_name, result)
  File "C:\Users\apukh\AppData\Local\Programs\Python\Python310\lib\site-packages\telebot\apihelper.py", line 184, in _check_result
    raise ApiTelegramException(method_name, result, result_json)
telebot.apihelper.ApiTelegramException: A request to the Telegram API was unsuccessful. Error code: 400. Description: Bad Request: chat not found
2022-05-20 01:01:40,793: Problem added as number 1 by user 2008767674
 {'issolved': False, 'next_reminder': 1652998420, 'date': 1652997700, 'text': 'Отсутствует', 'number': 1, 'photos': [{'name': 'BQACAgIAAxkBAAEBZt1ihr5PT3Qc1KOf7lSgyjgWdT4pdgACnhsAAi-KMUhedwwPiQGIxSQE.jpg', 'media_group_id': '13223981694267666'}], 'howPointsToSendToOperator': 3}
2022-05-20 01:01:40,801: File by For 2008767674
2022-05-20 01:01:44,667: Exception in sending to the operator via telegram:
A request to the Telegram API was unsuccessful. Error code: 400. Description: Bad Request: chat not found
Traceback (most recent call last):
  File "C:\Users\apukh\OneDrive\Документы\TelegramBotAssistant\ToOperatorByTelegramSender.py", line 34, in send_to_operator
    bot.send_media_group(operator_data["chat_id"], media)
  File "C:\Users\apukh\AppData\Local\Programs\Python\Python310\lib\site-packages\telebot\__init__.py", line 1355, in send_media_group
    result = apihelper.send_media_group(
  File "C:\Users\apukh\AppData\Local\Programs\Python\Python310\lib\site-packages\telebot\apihelper.py", line 496, in send_media_group
    return _make_request(
  File "C:\Users\apukh\AppData\Local\Programs\Python\Python310\lib\site-packages\telebot\apihelper.py", line 157, in _make_request
    json_result = _check_result(method_name, result)
  File "C:\Users\apukh\AppData\Local\Programs\Python\Python310\lib\site-packages\telebot\apihelper.py", line 184, in _check_result
    raise ApiTelegramException(method_name, result, result_json)
telebot.apihelper.ApiTelegramException: A request to the Telegram API was unsuccessful. Error code: 400. Description: Bad Request: chat not found
2022-05-20 01:03:22,209: Problem added as number 2 by user 2008767674
 {'issolved': False, 'next_reminder': 1652998522, 'date': 1652997802, 'text': 'sadf', 'number': 2, 'photos': [], 'howPointsToSendToOperator': 3}
2022-05-24 21:36:34,124: User's personal data received (2008767674):
{'deleted': False, 'firstname': 'А6вг', 'lastname': '6вгв', 'subdivision': 'Гвгв', 'email': 'Швв. @', 'phonenumber': '626'}
2022-05-24 21:36:36,333: Problem added as number 0 by user 2008767674
 {'issolved': False, 'next_reminder': 1653418116, 'date': 1653417396, 'text': 'Рввр', 'number': 0, 'photos': [], 'howPointsToSendToOperator': 3}
2022-05-26 22:07:59,925: User's personal data received (2008767674):
{'deleted': False, 'firstname': 'Шугу', 'lastname': 'Гугу', 'subdivision': 'Гкгк', 'email': '. @', 'phonenumber': '55'}
2022-05-26 22:08:02,072: Problem added as number 0 by user 2008767674
 {'issolved': False, 'next_reminder': 1653592091, 'date': 1653592081, 'text': 'Коок', 'number': 0, 'photos': [], 'howPointsToSendToOperator': 3}
2022-05-26 22:08:14,085: Photo by For 2008767674
2022-05-26 22:08:14,405: Photo by For 2008767674
2022-05-26 22:08:16,817: Problem added as number 1 by user 2008767674
 {'issolved': False, 'next_reminder': 1653592106, 'date': 1653592096, 'text': 'Коок', 'number': 1, 'photos': [], 'howPointsToSendToOperator': 3}
2022-05-26 22:08:45,715: Photo by For 2008767674
2022-05-26 22:08:46,482: Photo by For 2008767674
2022-05-26 22:08:52,312: Problem added as number 2 by user 2008767674
 {'issolved': False, 'next_reminder': 1653592142, 'date': 1653592132, 'text': 'Лккл', 'number': 2, 'photos': [], 'howPointsToSendToOperator': 3}
2022-05-27 22:27:29,536: User's personal data received (2008767674):
{'deleted': False, 'firstname': '6e6eyey', 'lastname': 'Ueye', 'subdivision': 'Uu3', 'email': '. @', 'phonenumber': '737'}
2022-05-27 22:27:31,519: Problem added as number 0 by user 2008767674
 {'issolved': False, 'next_reminder': 1653679661, 'date': 1653679651, 'text': 'Ydy', 'number': 0, 'photos': [], 'howPointsToSendToOperator': 3}
2022-05-27 22:28:01,121: Photo by For 2008767674
2022-05-27 22:28:01,546: Photo by For 2008767674
2022-05-27 22:28:03,356: Problem added as number 1 by user 2008767674
 {'issolved': False, 'next_reminder': 1653679693, 'date': 1653679683, 'text': 'H', 'number': 1, 'photos': [], 'howPointsToSendToOperator': 3}
2022-05-27 22:28:17,504: Problem added as number 2 by user 2008767674
 {'issolved': False, 'next_reminder': 1653679707, 'date': 1653679697, 'text': 'Ywy', 'number': 2, 'photos': [], 'howPointsToSendToOperator': 3}
